Workbook

Sheet Backup-Correos
A1: Servidor | B1: Carpeta | C1: Carpeta 1 | D1: Carpeta 2 | E1: Carpeta 3 | F1: Archivo | G1: CLOUD | H1: FECHA CARGA | I1: TamPST | J1: Tam OneDrive | K1: Columna1
A2: Docking | B2: Disco Duro D | C2: ORGANIZADO6 | D2: ATP | E2: Backup Karen Tovar | F2: Backup KarenTovar.pst | G2: Onedrive | H2: 45995 | I2: 20 GB
A3: Docking | B3: Disco Duro D | C3: ORGANIZADO6 | D3: ATP | E3: Backup Jeinson Montenegro | F3: BackupJeinsonMontenegro.pst | G3: Onedrive | H3: 45995 | I3: 8 GB | J3: 2 GB
A4: Docking | B4: Disco Duro D | C4: ORGANIZADO6 | D4: ATP | E4: Backup Jhonatan Rodriguez | F4: BackupJhonatanRodriguez.pst | G4: Onedrive | H4: 46000 | I4: 0.9 GB
A5: Docking | B5: Disco Duro D | C5: ORGANIZADO6 | D5: ATP | E5: Backup Sandro Zabaleta | F5: BackupSandroZabaleta.pst | G5: Onedrive | H5: 46001 | I5: 21 GB | J5: 2.5 GB
A6: Docking | B6: Disco Duro D | C6: ORGANIZADO6 | D6: ATP | E6: Backup Jairo Munoz | F6: BackupJairoMunoz.pst | G6: Onedrive | H6: 46007 | I6: 24 GB | J6: 16 GB
A7: Docking | B7: Disco Duro D | C7: ORGANIZADO6 | D7: ATP | E7: Backup David Lopez | F7: BackupDavidLopez.pst | G7: Onedrive | H7: 46007 | I7: 17 GB | J7: 0
A8: Docking | B8: Disco Duro D | C8: ORGANIZADO6 | D8: ATP | E8: Backup Cristian Cely | F8: BackupCristianCely.pst | G8: Onedrive | H8: 46036 | I8: 12 GB | J8: 30 GB
A9: Docking | B9: Disco Duro D | C9: ORGANIZADO6 | D9: ATP | E9: PST Diana Lopez | F9: diana.lopez.b@grupoconectar.co | G9: PST | H9: 46126 | I9: 6,34 GB | J9: 6,49 GB
A10: Docking | B10: Disco Duro D | C10: ORGANIZADO6 | D10: ATP | E10: PST Gestion de Permisos | F10: gestiondepermisosadmon@grupoconectar.co | G10: PST | H10: 46126 | I10: 6,13 GB | J10: 67,7 MB
A11: Docking | B11: Disco Duro D | C11: ORGANIZADO6 | D11: AZTECA | E11: BackUp Jhon Moreno | F11: jhon.moreno@grupoconectar.co | G11: PST | H11: 46197 | I11: 52 GB
A12: Docking | B12: Disco Duro D | C12: ORGANIZADO6 | D12: AZTECA | E12: BackUp Marolyn Muñoz | F12: marolyn.munoz@grupoconectar.co | G12: PST | H12: 46198 | I12: 4.9GB | J12: 0.2 GB
A13: Docking | B13: Disco Duro D | C13: ORGANIZADO6 | D13: AZTECA | E13: BackUp Edwin Soto | F13: edwin.soto@grupoconectar.co | G13: Onedrive | H13: 46204 | I13: 29.1GB | J13: 32.1GB
A14: Docking | B14: Disco Duro D | C14: ORGANIZADO6 | D14: AZTECA | E14: Backup Conectar Azteca | F14: conectar.azteca@grupoconectar.co | G14: OneDrive | H14: 46217 | I14: 1.4 GB | J14: 1.3 GB
A15: Docking | B15: Disco Duro D | C15: ORGANIZADO6 | D15: AZTECA | E15: Backup Miguel Ricardo | F15: backupMiguelRicardo | G15: OneDrive | H15: 46226 | I15: 50,5 GB | J15: 32.4GB
A16: Docking | B16: Disco Duro D | C16: ORGANIZADO6 | D16: CLARO R3 | E16: Backup Luis Agudelo | F16: BackupLuisAgudelo.pst | G16: EO | H16: 45662 | I16: 11 GB | J16: 0
A17: Docking | B17: Disco Duro D | C17: ORGANIZADO6 | D17: CLARO R3 | E17: Backup Yerli Romero | F17: BackupYerliRomero.pst | G17: EO | H17: 45664 | I17: 12 GB | J17: 2.13 GB
A18: Docking | B18: Disco Duro D | C18: ORGANIZADO6 | D18: CLARO R3 | E18: Backup Jonierth Velasquez | F18: BackupJonierthVelasquez.pst | G18: OneDrive | H18: 45666 | I18: 50 GB | J18: 1 GB
A19: Docking | B19: Disco Duro D | C19: ORGANIZADO6 | D19: CLARO R3 | E19: Backup Jeferson Bedoya | F19: BackupJefersonBedoya.pst | G19: Onedrive | H19: 45996 | I19: 3.5 GB | J19: 10 MB
A20: Docking | B20: Disco Duro D | C20: ORGANIZADO6 | D20: CLARO R3 | E20: Backup Paula Marulanda | F20: BackupPaulaMarulanda.pst | G20: Onedrive | H20: 45996 | I20: 9.7 GB | J20: 6 GB
A21: Docking | B21: Disco Duro D | C21: ORGANIZADO6 | D21: CLARO R3 | E21: Backup Maria Medellin | F21: BackupMariaMedellin.pst | G21: Onedrive | H21: 46000 | I21: 9.7 GB | J21: 3 GB
A22: Docking | B22: Disco Duro D | C22: ORGANIZADO6 | D22: CLARO R3 | E22: Backup Proyectos Palmira | F22: BackupProyectosPalmira.pst | G22: Onedrive | H22: 46000 | I22: 18.2 GB | J22: 280 MB
A23: Docking | B23: Disco Duro D | C23: ORGANIZADO6 | D23: CLARO R3 | E23: Backup Jimmy Ballen | F23: BackupJimmyBallen.pst | G23: solo pst | H23: 46002 | I23: 4.3 GB
A24: Docking | B24: Disco Duro D | C24: ORGANIZADO6 | D24: CLARO R3 | E24: Backup Eric Orjuela | F24: BackupEricOrjuela.pst | G24: solo pst | H24: 46003 | I24: 7.1 GB
A25: Docking | B25: Disco Duro D | C25: ORGANIZADO6 | D25: CLARO R3 | E25: Backup Ivan Arias | F25: BackupIvanArias.pst | G25: Onedrive | H25: 46007 | I25: 63 GB | J25: 6 GB
A26: Docking | B26: Disco Duro D | C26: ORGANIZADO6 | D26: CLARO R3 | E26: Backup Ruben Solano | F26: BackupRubenSolano.pst | G26: Onedrive | H26: 46008 | I26: 20 GB | J26: 6 GB
A27: Docking | B27: Disco Duro D | C27: ORGANIZADO6 | D27: CLARO R3 | E27: Backup Andrea Corredor | F27: BackupAndreaCorredor.pst | G27: Onedrive | H27: 46009 | I27: 48.5 GB | J27: 24.2 GB
A28: Docking | B28: Disco Duro D | C28: ORGANIZADO6 | D28: CLARO R3 | E28: Backup Diego Rozo | F28: BackupDiegoRozo.pst | G28: EO | H28: 46009 | I28: 13GB
A29: Docking | B29: Disco Duro D | C29: ORGANIZADO6 | D29: CLARO R3 | E29: Backup Steven Cedano | F29: BackupStevenCedano.pst | G29: OneDrive | H29: 46009 | I29: 6.1 GB | J29: 28 GB
A30: Docking | B30: Disco Duro D | C30: ORGANIZADO6 | D30: CLARO R3 | E30: Backup Ana Infante | F30: BackupAnaInfante.pst | G30: OneDrive | H30: 46010 | I30: 1.5 GB | J30: 20 GB
A31: Docking | B31: Disco Duro D | C31: ORGANIZADO6 | D31: CLARO R3 | E31: Backup Angelica Ramirez | F31: BackupAngelicaRamirez.pst | G31: EO | H31: 46010 | I31: 12.5 GB
A32: Docking | B32: Disco Duro D | C32: ORGANIZADO6 | D32: CLARO R3 | E32: Backup Miguel Alonso | F32: BackupMiguelAlonso.pst | G32: OneDrive | H32: 46014 | I32: 49 GB | J32: 2 GB
A33: Docking | B33: Disco Duro D | C33: ORGANIZADO6 | D33: CLARO R3 | E33: Backup Walter Burbano | F33: BackupWalterBurbano.pst | G33: OneDrive | H33: 46014 | I33: 51 GB | J33: 2.4 GB
A34: Docking | B34: Disco Duro D | C34: ORGANIZADO6 | D34: CLARO R3 | E34: Backup Supervisores Cali | F34: BackupSupervisoresCali.pst | G34: EO | H34: 46017 | I34: 2 GB
A35: Docking | B35: Disco Duro D | C35: ORGANIZADO6 | D35: CLARO R3 | E35: Backup German Molano | F35: BackupGermanMolano.pst | G35: OneDrive | H35: 46017 | I35: 47 GB | J35: 200 MB
A36: Docking | B36: Disco Duro D | C36: ORGANIZADO6 | D36: CLARO R3 | E36: Backup Jonathan Correa | F36: BackupJonathanCorrea.pst | G36: solo pst | H36: 46036 | I36: 3 GB | J36: 0
A37: Docking | B37: Disco Duro D | C37: ORGANIZADO6 | D37: CLARO R3 | E37: Backup Jhoan Ortiz | F37: BackupJhoanOrtiz.pst | G37: OneDrive | H37: 46037 | I37: 12 GB | J37: 8 GB
A38: Docking | B38: Disco Duro D | C38: ORGANIZADO6 | D38: CLARO R3 | E38: Backup Maria Sierra | F38: BackupMariaSierra.pst | G38: OneDrive | H38: 46041 | I38: 18 GB | J38: 25.8 GB
A39: Docking | B39: Disco Duro D | C39: ORGANIZADO6 | D39: CLARO R3 | E39: Backup Derly Quintero | F39: BackupderlyQuintero.pst | G39: OneDrive | H39: 46055 | I39: 13 GB | J39: 5 GB
A40: Docking | B40: Disco Duro D | C40: ORGANIZADO6 | D40: CLARO R3 | E40: Backup Jose Maestre | F40: BackupJoseMaestre.pst | G40: OneDrive | H40: 46057 | I40: 48 GB | J40: 100 MB
...

Sheet CORREOS-PERÚ
A1: FECHA_CREACION | B1: CIUDAD LABOR | C1: PRECIO USD | D1: DOMINIO | E1: PLAN | F1: NUM_DOCUMENTO | G1: NOMBRE_USUARIO | H1: OBSERVACIÓN (Solicitante) | I1: APELLIDO NOMBRE | J1: CARGO | K1: CU1 | L1: CU1-PROCESO | M1: CU1-REGIONAL | N1: CU1-CIUDAD | O1: CU3 | P1: CU3-CLIENTE | Q1: CU3-LINEA DE NEGOCIO | R1: CU3-PROYECTO | S1: GRUPO | T1: EMPRESA | U1: PROCESO GEN | V1: % PROYECTO | W1: Baja Correo
A2: 43710 | B2: LIMA | C2: 7.56 | D2: (G) .TELECOM | E2: Google Workspace Business Starter | F2: 46151732 | G2: compras@conectartelecomunicaciones.com | H2: Wendy Lopez (Consulta) | I2: =VLOOKUP(F2,'PLANTA PERU'!A:AL,2,0) -> LOPEZ UCHUYA KATHERINE WENDY | J2: =VLOOKUP(F2,'PLANTA PERU'!A:AL,10,0) -> JEFE DE ADMINISTRACION Y SCS | K2: IGUL | L2: =VLOOKUP(F2,'PLANTA PERU'!A:AD,7,0) -> 0 | M2: NA | N2: =VLOOKUP(F2,'PLANTA PERU'!A:AD,12,0) -> TERMINO FIJO | O2: CSOM | P2: CLARO PERU | Q2: NA | R2: NA | S2: NA | T2: TELECOMUNICACIONES SAC | U2: NA | V2: NA
A3: 43866 | B3: LIMA | C3: 7.56 | D3: (G) .TELECOM | E3: Google Workspace Business Starter | F3: 73445684 | G3: Katherin.Maldonado@conectartelecomunicaciones.com | H3: LIMA | I3: =VLOOKUP(F3,'PLANTA PERU'!A:AL,2,0) -> #N/A | J3: =VLOOKUP(F3,'PLANTA PERU'!A:AL,10,0) -> #N/A | K3: IGUL | L3: =VLOOKUP(F3,'PLANTA PERU'!A:AD,7,0) -> #N/A | M3: NA | N3: =VLOOKUP(F3,'PLANTA PERU'!A:AD,12,0) -> #N/A | O3: CSOM | P3: CLARO PERU | Q3: NA | R3: NA | S3: NA | T3: TELECOMUNICACIONES SAC | U3: NA | V3: NA
A4: 44070 | B4: LIMA | C4: 7.56 | D4: (G) .TELECOM | E4: Google Workspace Business Starter | G4: actasdigitales@conectartelecomunicaciones.com | H4: LIMA | I4: =VLOOKUP(F4,'PLANTA PERU'!A:AL,2,0) -> #N/A | J4: =VLOOKUP(F4,'PLANTA PERU'!A:AL,10,0) -> #N/A | K4: IGUL | L4: =VLOOKUP(F4,'PLANTA PERU'!A:AD,7,0) -> #N/A | M4: NA | N4: =VLOOKUP(F4,'PLANTA PERU'!A:AD,12,0) -> #N/A | O4: CSOM | P4: CLARO PERU | Q4: NA | R4: NA | S4: NA | T4: TELECOMUNICACIONES SAC | U4: NA | V4: NA
A5: 44364 | B5: LIMA | C5: 12.6 | D5: (M) .CO | E5: Microsoft 365 Empresa Estándar | F5: 4718074 | G5: carlos.porras@grupoconectar.co | H5: LIMA | I5: =VLOOKUP(F5,'PLANTA PERU'!A:AL,2,0) -> PORRAS TIBATA CARLOS MAURICIO | J5: =VLOOKUP(F5,'PLANTA PERU'!A:AL,10,0) -> GERENTE GENERAL & REGIONAL MANAGER | K5: IGUL | L5: =VLOOKUP(F5,'PLANTA PERU'!A:AD,7,0) -> 0 | M5: NA | N5: =VLOOKUP(F5,'PLANTA PERU'!A:AD,12,0) -> TERMINO FIJO | O5: MSIM | P5: CLARO PERU | Q5: NA | R5: NA | S5: NA | T5: TELECOMUNICACIONES SAC | U5: NA | V5: NA
A6: 45174 | B6: LIMA | C6: 6.3 | D6: (M) .CO | E6: Microsoft 365 Empresa Básico | F6: 74214133 | G6: winny.espinoza@grupoconectar.co | H6: WINNY KRISSEL ESPINOZA ARGANDOÑA | I6: =VLOOKUP(F6,'PLANTA PERU'!A:AL,2,0) -> ESPINOZA ARGANDO?A WINNY KRISSEL | J6: =VLOOKUP(F6,'PLANTA PERU'!A:AL,10,0) -> GERENTE DE OPERACIONES | K6: IGUL | L6: =VLOOKUP(F6,'PLANTA PERU'!A:AD,7,0) -> 0 | M6: NA | N6: =VLOOKUP(F6,'PLANTA PERU'!A:AD,12,0) -> 0 | O6: MSIM | P6: HUAWEI PERU | Q6: NA | R6: NA | S6: NA | T6: TELECOMUNICACIONES SAC | U6: NA | V6: NA
A7: 45029 | B7: LIMA | C7: 4.53 | D7: (M) .CO | E7: Exchange Online (Plan 1) | F7: 70390056 | G7: jeancarlos.alfaro@grupoconectar.co | H7: LIMA (Técnico Especialista) | I7: =VLOOKUP(F7,'PLANTA PERU'!A:AL,2,0) -> ALFARO RODRIGUEZ JEANCARLOS DAVID EDEY | J7: =VLOOKUP(F7,'PLANTA PERU'!A:AL,10,0) -> TECNICO ESPECIALISTA | K7: IGUL | L7: =VLOOKUP(F7,'PLANTA PERU'!A:AD,7,0) -> 0 | M7: NA | N7: =VLOOKUP(F7,'PLANTA PERU'!A:AD,12,0) -> INDEFINIDO | O7: HNFM | P7: HUAWEI PERU | Q7: NA | R7: NA | S7: NA | T7: TELECOMUNICACIONES SAC | U7: NA | V7: NA
A8: 45296 | B8: LIMA | C8: 6.3 | D8: (M) .CO | E8: Microsoft 365 Empresa Básico | F8: 48685035 | G8: elizabeth.salazar@grupoconectar.co | H8: LIMA elizabeth Salazar Nizama | I8: =VLOOKUP(F8,'PLANTA PERU'!A:AL,2,0) -> SALAZAR NIZAMA ELIZABETH MARLENE | J8: =VLOOKUP(F8,'PLANTA PERU'!A:AL,10,0) -> BACK OFFICE DE LIQUIDACION | K8: IGUL | L8: =VLOOKUP(F8,'PLANTA PERU'!A:AD,7,0) -> 0 | M8: NA | N8: =VLOOKUP(F8,'PLANTA PERU'!A:AD,12,0) -> TERMINO FIJO | O8: MSIM | P8: CLARO PERU | Q8: NA | R8: NA | S8: NA | T8: TELECOMUNICACIONES SAC | U8: NA | V8: NA
A9: 45238 | B9: LIMA | C9: 4.53 | D9: (M) .CO | E9: Exchange Online (Plan 1) | F9: 46461207 | G9: richard.espinoza@grupoconectar.co | H9: Richard Sebastianni Espinoza Mendoza (Raul Villanueva) | I9: =VLOOKUP(F9,'PLANTA PERU'!A:AL,2,0) -> ESPINOZA MENDOZA RICHARD SEBASTIANNI | J9: =VLOOKUP(F9,'PLANTA PERU'!A:AL,10,0) -> TECNICO JUNIOR TDP | K9: IGUL | L9: =VLOOKUP(F9,'PLANTA PERU'!A:AD,7,0) -> 0 | M9: NA | N9: =VLOOKUP(F9,'PLANTA PERU'!A:AD,12,0) -> TERMINO FIJO | O9: HNFM | P9: HUAWEI PERU | Q9: NA | R9: NA | S9: NA | T9: TELECOMUNICACIONES SAC | U9: NA | V9: NA
A10: 45140 | B10: LIMA | C10: 4.53 | D10: (M) .CO | E10: Exchange Online (Plan 1) | F10: 74988593 | G10: victor.baldeon@grupoconectar.co | H10: VICTOR ALBERTO BALDEON LOMA | I10: =VLOOKUP(F10,'PLANTA PERU'!A:AL,2,0) -> BALDEON LOMA VICTOR ALBERTO | J10: =VLOOKUP(F10,'PLANTA PERU'!A:AL,10,0) -> ANALISTA DE LIQUIDACION | K10: IGUL | L10: =VLOOKUP(F10,'PLANTA PERU'!A:AD,7,0) -> 0 | M10: NA | N10: =VLOOKUP(F10,'PLANTA PERU'!A:AD,12,0) -> 0 | O10: HNFM | P10: HUAWEI PERU | Q10: NA | R10: NA | S10: NA | T10: TELECOMUNICACIONES SAC | U10: NA | V10: NA
A11: 45140 | B11: LIMA | C11: 4.53 | D11: (M) .CO | E11: Exchange Online (Plan 1) | F11: 61106340 | G11: jairzinho.uribe@grupoconectar.co | H11: URIBE QUILCA JAIRZINHO SAMIR | I11: =VLOOKUP(F11,'PLANTA PERU'!A:AL,2,0) -> URIBE QUILCA JAIRZINHO SAMIR | J11: =VLOOKUP(F11,'PLANTA PERU'!A:AL,10,0) -> TECNICO JUNIOR TDP | K11: IGUL | L11: =VLOOKUP(F11,'PLANTA PERU'!A:AD,7,0) -> 0 | M11: NA | N11: =VLOOKUP(F11,'PLANTA PERU'!A:AD,12,0) -> TERMINO FIJO | O11: HNFM | P11: HUAWEI PERU | Q11: NA | R11: NA | S11: NA | T11: TELECOMUNICACIONES SAC | U11: NA | V11: NA
A12: 45140 | B12: LIMA | C12: 4.53 | D12: (M) .CO | E12: Exchange Online (Plan 1) | F12: 2013590 | G12: armando.esteves@grupoconectar.co | H12: Maikers Armando Esteves Hernandez (Raul Villanueva) | I12: =VLOOKUP(F12,'PLANTA PERU'!A:AL,2,0) -> ESTEVES HERNANDEZ MAIKERS ARMANDO | J12: =VLOOKUP(F12,'PLANTA PERU'!A:AL,10,0) -> TECNICO JUNIOR TDP | K12: IGUL | L12: =VLOOKUP(F12,'PLANTA PERU'!A:AD,7,0) -> 0 | M12: NA | N12: =VLOOKUP(F12,'PLANTA PERU'!A:AD,12,0) -> TERMINO FIJO | O12: HNFM | P12: HUAWEI PERU | Q12: NA | R12: NA | S12: NA | T12: TELECOMUNICACIONES SAC | U12: NA | V12: NA
A13: 45140 | B13: LIMA | C13: 6.3 | D13: (M) .CO | E13: Microsoft 365 Empresa Básico | F13: 40418047 | G13: rita.canales@grupoconectar.co | H13: LIMA, RITA CANALES | I13: =VLOOKUP(F13,'PLANTA PERU'!A:AL,2,0) -> CANALES QUI?E RITA GRACIELA | J13: =VLOOKUP(F13,'PLANTA PERU'!A:AL,10,0) -> BACKOFFICE N2 | K13: IGUL | L13: =VLOOKUP(F13,'PLANTA PERU'!A:AD,7,0) -> 0 | M13: NA | N13: =VLOOKUP(F13,'PLANTA PERU'!A:AD,12,0) -> 0 | O13: HNFM | P13: HUAWEI PERU | Q13: NA | R13: NA | S13: NA | T13: TELECOMUNICACIONES SAC | U13: NA | V13: NA
A14: 45140 | B14: LIMA | C14: 4.53 | D14: (M) .CO | E14: Exchange Online (Plan 1) | F14: 71028231 | G14: darwin.tiburcio@grupoconectar.co | H14: TIBURCIO NEIRA DARWIN LEANDRO | I14: =VLOOKUP(F14,'PLANTA PERU'!A:AL,2,0) -> TIBURCIO NEIRA DARWIN LEANDRO | J14: =VLOOKUP(F14,'PLANTA PERU'!A:AL,10,0) -> TECNICO ESPECIALISTA | K14: IGUL | L14: =VLOOKUP(F14,'PLANTA PERU'!A:AD,7,0) -> 0 | M14: NA | N14: =VLOOKUP(F14,'PLANTA PERU'!A:AD,12,0) -> TERMINO FIJO | O14: HNFM | P14: HUAWEI PERU | Q14: NA | R14: NA | S14: NA | T14: TELECOMUNICACIONES SAC | U14: NA | V14: NA
A15: 45140 | B15: LIMA | C15: 4.53 | D15: (M) .CO | E15: Exchange Online (Plan 1) | F15: 3105416 | G15: dennys.huerta@grupoconectar.co | H15: HUERTA ZAMBRANO DENNYS KEN | I15: =VLOOKUP(F15,'PLANTA PERU'!A:AL,2,0) -> HUERTA ZAMBRANO DENNYS KEN | J15: =VLOOKUP(F15,'PLANTA PERU'!A:AL,10,0) -> SUPERVISOR FLM | K15: IGUL | L15: =VLOOKUP(F15,'PLANTA PERU'!A:AD,7,0) -> 0 | M15: NA | N15: =VLOOKUP(F15,'PLANTA PERU'!A:AD,12,0) -> 0 | O15: HNFM | P15: HUAWEI PERU | Q15: NA | R15: NA | S15: NA | T15: TELECOMUNICACIONES SAC | U15: NA | V15: NA
A16: 45140 | B16: LIMA | C16: 4.53 | D16: (M) .CO | E16: Exchange Online (Plan 1) | F16: 70158066 | G16: Daniton.Huaman@grupoconectar.co | H16: LIMA | I16: =VLOOKUP(F16,'PLANTA PERU'!A:AL,2,0) -> HUAMAN HUAMAN DANITON | J16: =VLOOKUP(F16,'PLANTA PERU'!A:AL,10,0) -> TECNICO ESPECIALISTA | K16: IGUL | L16: =VLOOKUP(F16,'PLANTA PERU'!A:AD,7,0) -> 0 | M16: NA | N16: =VLOOKUP(F16,'PLANTA PERU'!A:AD,12,0) -> TERMINO FIJO | O16: HNFM | P16: HUAWEI PERU | Q16: NA | R16: NA | S16: NA | T16: TELECOMUNICACIONES SAC | U16: NA | V16: NA
... A33: 45050 | B33: LIMA | C33: 6.3 | D33: (M) .CO | E33: Microsoft 365 Empresa Básico | F33: 43630508 | G33: andrea.leon@grupoconectar.co | H33: Andrea Leon Serquin (William Muñoz) | I33: =VLOOKUP(F33,'PLANTA PERU'!A:AL,2,0) -> LEON SERQUIN ANDREA | J33: =VLOOKUP(F33,'PLANTA PERU'!A:AL,10,0) -> ANALISTA DE NOMINAS | K33: IGUL | L33: =VLOOKUP(F33,'PLANTA PERU'!A:AD,7,0) -> 0 | M33: NA | N33: =VLOOKUP(F33,'PLANTA PERU'!A:AD,12,0) -> TERMINO FIJO | O33: MSIM | P33: CLARO PERU | Q33: NA | R33: NA | S33: NA | T33: TELECOMUNICACIONES SAC | U33: NA | V33: NA
A34: 45229 | B34: LIMA | C34: 6.3 | D34: (M) .CO | E34: Microsoft 365 Empresa Básico | F34: 74870938 | G34: bruno.alaluna@grupoconectar.co | H34: ALALUNA GOMEZ BRUNO ORLANDO | I34: =VLOOKUP(F34,'PLANTA PERU'!A:AL,2,0) -> ALALUNA GOMEZ BRUNO ORLANDO | J34: =VLOOKUP(F34,'PLANTA PERU'!A:AL,10,0) -> COORDINADOR LOGISTICO | K34: IGUL | L34: =VLOOKUP(F34,'PLANTA PERU'!A:AD,7,0) -> 0 | M34: NA | N34: =VLOOKUP(F34,'PLANTA PERU'!A:AD,12,0) -> 0 | O34: MSIM | P34: CLARO PERU | Q34: NA | R34: NA | S34: NA | T34: TELECOMUNICACIONES SAC | U34: NA | V34: NA | W34: REASIGNAR A: BERROSPI CHAUPIS IVAN RODRIGO DNI: 76297793
A35: 45106 | B35: LIMA | C35: 4.53 | D35: (M) .CO | E35: Exchange Online (Plan 1) | F35: 8890271 | G35: ivan.morales@grupoconectar.co | H35: LIMA IVÁN L MORALES S | I35: =VLOOKUP(F35,'PLANTA PERU'!A:AL,2,0) -> MORALES SOTELO IVAN LUIS | J35: =VLOOKUP(F35,'PLANTA PERU'!A:AL,10,0) -> SUPERVISOR DE INSTALACIONES | K35: IGUL | L35: =VLOOKUP(F35,'PLANTA PERU'!A:AD,7,0) -> 0 | M35: NA | N35: =VLOOKUP(F35,'PLANTA PERU'!A:AD,12,0) -> TERMINO FIJO | O35: MSIM | P35: CLARO PERU | Q35: NA | R35: NA | S35: NA | T35: TELECOMUNICACIONES SAC | U35: NA | V35: NA
A36: 45106 | B36: LIMA | C36: 6.3 | D36: (M) .CO | E36: Microsoft 365 Empresa Básico | F36: 9302925 | G36: edwin.molina@grupoconectar.co | H36: LIMA EDWIN M MOLINA V | I36: =VLOOKUP(F36,'PLANTA PERU'!A:AL,2,0) -> MOLINA VILA EDWIN MANUEL | J36: =VLOOKUP(F36,'PLANTA PERU'!A:AL,10,0) -> COORDINADOR DE SST | K36: IGUL | L36: =VLOOKUP(F36,'PLANTA PERU'!A:AD,7,0) -> 0 | M36: NA | N36: =VLOOKUP(F36,'PLANTA PERU'!A:AD,12,0) -> TERMINO FIJO | O36: MSIM | P36: CLARO PERU | Q36: NA | R36: NA | S36: NA | T36: TELECOMUNICACIONES SAC | U36: NA | V36: NA
A37: 45113 | B37: LIMA | C37: 6.3 | D37: (M) .CO | E37: Microsoft 365 Empresa Básico | F37: 46143644 | G37: meri.albornoz@grupoconectar.co | H37: MERI YENI ALBORNOZ VIGURIA | I37: =VLOOKUP(F37,'PLANTA PERU'!A:AL,2,0) -> ALBORNOZ VIGURIA MERI YENI | J37: =VLOOKUP(F37,'PLANTA PERU'!A:AL,10,0) -> AUXILIAR CONTABLE | K37: IGUL | L37: =VLOOKUP(F37,'PLANTA PERU'!A:AD,7,0) -> 0 | M37: NA | N37: =VLOOKUP(F37,'PLANTA PERU'!A:AD,12,0) -> 0 | O37: MSIM | P37: CLARO PERU | Q37: NA | R37: NA | S37: NA | T37: TELECOMUNICACIONES SAC | U37: NA | V37: NA
A38: 45113 | B38: LIMA | C38: 6.3 | D38: (M) .CO | E38: Microsoft 365 Empresa Básico | F38: 44156080 | G38: lucia.tello@grupoconectar.co | H38: Lucia Luz Tello Cabeza (William Muñoz) | I38: =VLOOKUP(F38,'PLANTA PERU'!A:AL,2,0) -> TELLO CABEZA LUCIA LUZ | J38: =VLOOKUP(F38,'PLANTA PERU'!A:AL,10,0) -> TESORERA | K38: IGUL | L38: =VLOOKUP(F38,'PLANTA PERU'!A:AD,7,0) -> 0 | M38: NA | N38: =VLOOKUP(F38,'PLANTA PERU'!A:AD,12,0) -> 0 | O38: MSIM | P38: CLARO PERU | Q38: NA | R38: NA | S38: NA | T38: TELECOMUNICACIONES SAC | U38: NA | V38: NA
A39: 45113 | B39: LIMA | C39: 6.3 | D39: (M) .CO | E39: Microsoft 365 Empresa Básico | F39: 44285911 | G39: almacen.sur@grupoconectar.co | H39: LIMA ALMACEN BASE SUR | I39: =VLOOKUP(F39,'PLANTA PERU'!A:AL,2,0) -> CAYCHO PACHECO MARIO MIGUEL | J39: =VLOOKUP(F39,'PLANTA PERU'!A:AL,10,0) -> SUPERVISOR LOGISTICO | K39: IGUL | L39: =VLOOKUP(F39,'PLANTA PERU'!A:AD,7,0) -> 0 | M39: NA | N39: =VLOOKUP(F39,'PLANTA PERU'!A:AD,12,0) -> TERMINO FIJO | O39: MSIM | P39: CLARO PERU | Q39: NA | R39: NA | S39: NA | T39: TELECOMUNICACIONES SAC | U39: NA | V39: NA
A40: 45119 | B40: LIMA | C40: 6.3 | D40: (M) .CO | E40: Microsoft 365 Empresa Básico | F40: 76297793 | G40: ivan.berrospi@grupoconectar.co | H40: Ivan Rodrigo Berrospi Chaupis (William Muñoz) | I40: =VLOOKUP(F40,'PLANTA PERU'!A:AL,2,0) -> BERROSPI CHAUPIS IVAN RODRIGO | J40: =VLOOKUP(F40,'PLANTA PERU'!A:AL,10,0) -> ANALISTA FINANCIERO | K40: IGUL | L40: =VLOOKUP(F40,'PLANTA PERU'!A:AD,7,0) -> 0 | M40: NA | N40: =VLOOKUP(F40,'PLANTA PERU'!A:AD,12,0) -> INDEFINIDO | O40: MSIM | P40: CLARO PERU | Q40: NA | R40: NA | S40: NA | T40: TELECOMUNICACIONES SAC | U40: NA | V40: NA
A41: 45119 | B41: LIMA | C41: 6.3 | D41: (M) .CO | E41: Microsoft 365 Empresa Básico | F41: 44277521 | G41: jean.melendez@grupoconectar.co | H41: JEAN PIERRE MELENDEZ ALCAZAR | I41: =VLOOKUP(F41,'PLANTA PERU'!A:AL,2,0) -> MELENDEZ ALCAZAR | J41: =VLOOKUP(F41,'PLANTA PERU'!A:AL,10,0) -> SUPERVISOR FLM ENTEL | K41: IGUL | L41: =VLOOKUP(F41,'PLANTA PERU'!A:AD,7,0) -> 0 | M41: NA | N41: =VLOOKUP(F41,'PLANTA PERU'!A:AD,12,0) -> 0 | O41: MSIM | P41: CLARO PERU | Q41: NA | R41: NA | S41: NA | T41: TELECOMUNICACIONES SAC | U41: NA | V41: NA
A42: 45140 | B42: LIMA | C42: 4.53 | D42: (M) .CO | E42: Exchange Online (Plan 1) | F42: 74941839 | G42: Segundo.Torrejon@grupoconectar.co | H42: SEGUNDO J TORREJÓN P | I42: =VLOOKUP(F42,'PLANTA PERU'!A:AL,2,0) -> TORREJON PULCE SEGUNDO JHONATAN | J42: =VLOOKUP(F42,'PLANTA PERU'!A:AL,10,0) -> TECNICO ESPECIALISTA | K42: IGUL | L42: =VLOOKUP(F42,'PLANTA PERU'!A:AD,7,0) -> 0 | M42: NA | N42: =VLOOKUP(F42,'PLANTA PERU'!A:AD,12,0) -> TERMINO FIJO | O42: HNFM | P42: HUAWEI PERU | Q42: NA | R42: NA | S42: NA | T42: TELECOMUNICACIONES SAC | U42: NA | V42: NA
A43: 45216 | B43: LIMA | C43: 6.3 | D43: (M) .CO | E43: Microsoft 365 Empresa Básico | F43: 70566879 | G43: caleb.alburqueque@grupoconectar.co | H43: ALBURQUEQUE RUEDA CALEB MIGUEL | I43: =VLOOKUP(F43,'PLANTA PERU'!A:AL,2,0) -> ALBURQUEQUE RUEDA CALEB MIGUEL | J43: =VLOOKUP(F43,'PLANTA PERU'!A:AL,10,0) -> AUXILIAR DE LIQUIDACI?N | K43: IGUL | L43: =VLOOKUP(F43,'PLANTA PERU'!A:AD,7,0) -> 0 | M43: NA | N43: =VLOOKUP(F43,'PLANTA PERU'!A:AD,12,0) -> 0 | O43: MSIM | P43: CLARO PERU | Q43: NA | R43: NA | S43: NA | T43: TELECOMUNICACIONES SAC | U43: NA | V43: NA
A44: 45163 | B44: LIMA | C44: 6.3 | D44: (M) .CO | E44: Microsoft 365 Empresa Básico | F44: 71490074 | G44: eliot.chavez@grupoconectar.co | H44: ELIOT MARTÍN CHAVEZ P | I44: =VLOOKUP(F44,'PLANTA PERU'!A:AL,2,0) -> CHAVEZ PALOMINO ELIOT MARTIN | J44: =VLOOKUP(F44,'PLANTA PERU'!A:AL,10,0) -> ANALISTA ADMINISTRATIVO | K44: IGUL | L44: =VLOOKUP(F44,'PLANTA PERU'!A:AD,7,0) -> 0 | M44: NA | N44: =VLOOKUP(F44,'PLANTA PERU'!A:AD,12,0) -> TERMINO FIJO | O44: MSIM | P44: CLARO PERU | Q44: NA | R44: NA | S44: NA | T44: TELECOMUNICACIONES SAC | U44: NA | V44: NA
A45: 45226 | B45: LIMA | C45: 6.3 | D45: (M) .CO | E45: Microsoft 365 Empresa Básico | F45: 76516783 | G45: kevin.herrera@grupoconectar.co | H45: HERRERA U KEVIN S | I45: =VLOOKUP(F45,'PLANTA PERU'!A:AL,2,0) -> HERRERA UCHUYA KEVIN STEVEN | J45: =VLOOKUP(F45,'PLANTA PERU'!A:AL,10,0) -> ANALISTA SSOMA | K45: IGUL | L45: =VLOOKUP(F45,'PLANTA PERU'!A:AD,7,0) -> 0 | M45: NA | N45: =VLOOKUP(F45,'PLANTA PERU'!A:AD,12,0) -> TERMINO FIJO | O45: HNFM | P45: HUAWEI PERU | Q45: NA | R45: NA | S45: NA | T45: TELECOMUNICACIONES SAC | U45: NA | V45: NA
A46: 45245 | B46: LIMA | C46: 4.53 | D46: (M) .CO | E46: Exchange Online (Plan 1) | F46: 5054577 | G46: ana.salazar@grupoconectar.co | H46: ANA ROSA SALAZAR RODRIGUEZ | I46: =VLOOKUP(F46,'PLANTA PERU'!A:AL,2,0) -> SALAZAR RODRIGUEZ ANA ROSA | J46: =VLOOKUP(F46,'PLANTA PERU'!A:AL,10,0) -> TECNICO JUNIOR | K46: IGUL | L46: =VLOOKUP(F46,'PLANTA PERU'!A:AD,7,0) -> 0 | M46: NA | N46: =VLOOKUP(F46,'PLANTA PERU'!A:AD,12,0) -> TERMINO FIJO | O46: MSIM | P46: CLARO PERU | Q46: NA | R46: NA | S46: NA | T46: TELECOMUNICACIONES SAC | U46: NA | V46: NA
... A62: 45343 | B62: LIMA | C62: 4.53 | D62: (M) .CO | E62: Exchange Online (Plan 1) | F62: 76765238 | G62: piero.solier@grupoconectar.co | H62: Piero Rodrigo Solier Galvez (Raul Villanueva) | I62: =VLOOKUP(F62,'PLANTA PERU'!A:AL,2,0) -> SOLIER GALVEZ PIERO RODRIGO | J62: =VLOOKUP(F62,'PLANTA PERU'!A:AL,10,0) -> BACK OFFICE | K62: IGUL | L62: =VLOOKUP(F62,'PLANTA PERU'!A:AD,7,0) -> 0 | M62: NA | N62: =VLOOKUP(F62,'PLANTA PERU'!A:AD,12,0) -> TERMINO FIJO | O62: HNFM | P62: HUAWEI PERU | Q62: NA | R62: NA | S62: NA | T62: TELECOMUNICACIONES SAC | U62: NA | V62: NA
A63: 45343 | B63: LIMA | C63: 4.53 | D63: (M) .CO | E63: Exchange Online (Plan 1) | F63: 75224735 | G63: cesar.curro@grupoconectar.co | H63: Cesar Antonio Curro Mendoza (William Muñoz) | I63: =VLOOKUP(F63,'PLANTA PERU'!A:AL,2,0) -> CURRO MENDOZA CESAR ANTONIO | J63: =VLOOKUP(F63,'PLANTA PERU'!A:AL,10,0) -> TECNICO ESPECIALISTA | K63: IGUL | L63: =VLOOKUP(F63,'PLANTA PERU'!A:AD,7,0) -> 0 | M63: NA | N63: =VLOOKUP(F63,'PLANTA PERU'!A:AD,12,0) -> TERMINO FIJO | O63: HNFM | P63: HUAWEI PERU | Q63: NA | R63: NA | S63: NA | T63: TELECOMUNICACIONES SAC | U63: NA | V63: NA | W63: SU APOYO PARA RECUPERAR EL ACCESO, TIENE REGISTRADO UN NUMERO EL CUAL NO TENEMOS PARA RECUPERAR SU CONTRASEÑA
A64: 45343 | B64: LIMA | C64: 4.53 | D64: (M) .CO | E64: Exchange Online (Plan 1) | F64: 73046819 | G64: eduardo.paredes@grupoconectar.co | H64: Christian Eduardo Paredes Marroquin (William Muñoz) | I64: =VLOOKUP(F64,'PLANTA PERU'!A:AL,2,0) -> PAREDES MARROQUIN CHRISTIAN EDUARDO | J64: =VLOOKUP(F64,'PLANTA PERU'!A:AL,10,0) -> TECNICO ESPECIALISTA | K64: IGUL | L64: =VLOOKUP(F64,'PLANTA PERU'!A:AD,7,0) -> 0 | M64: NA | N64: =VLOOKUP(F64,'PLANTA PERU'!A:AD,12,0) -> TERMINO FIJO | O64: MSIM | P64: CLARO PERU | Q64: NA | R64: NA | S64: NA | T64: TELECOMUNICACIONES SAC | U64: NA | V64: NA
A65: 45343 | B65: LIMA | C65: 4.53 | D65: (M) .CO | E65: Exchange Online (Plan 1) | F65: 72533709 | G65: joseph.garcia@grupoconectar.co | H65: Joseph Ronald Garcia Moscoso (Raul Villanueva) | I65: =VLOOKUP(F65,'PLANTA PERU'!A:AL,2,0) -> GARCIA MOSCOSO JOSEPH RONALD | J65: =VLOOKUP(F65,'PLANTA PERU'!A:AL,10,0) -> BACK OFFICE | K65: IGUL | L65: =VLOOKUP(F65,'PLANTA PERU'!A:AD,7,0) -> 0 | M65: NA | N65: =VLOOKUP(F65,'PLANTA PERU'!A:AD,12,0) -> TERMINO FIJO | O65: HNFM | P65: HUAWEI PERU | Q65: NA | R65: NA | S65: NA | T65: TELECOMUNICACIONES SAC | U65: NA | V65: NA
A66: 45343 | B66: LIMA | C66: 4.53 | D66: (M) .CO | E66: Exchange Online (Plan 1) | F66: 73046819 | G66: christian.paredes@grupoconectar.co | H66: PAREDES MARROQUIN CHRISTIAN EDUARDO | I66: =VLOOKUP(F66,'PLANTA PERU'!A:AL,2,0) -> PAREDES MARROQUIN CHRISTIAN EDUARDO | J66: =VLOOKUP(F66,'PLANTA PERU'!A:AL,10,0) -> TECNICO ESPECIALISTA | K66: IGUL | L66: =VLOOKUP(F66,'PLANTA PERU'!A:AD,7,0) -> 0 | M66: NA | N66: =VLOOKUP(F66,'PLANTA PERU'!A:AD,12,0) -> TERMINO FIJO | O66: HNFM | P66: HUAWEI PERU | Q66: NA | R66: NA | S66: NA | T66: TELECOMUNICACIONES SAC | U66: NA | V66: NA
A67: 45343 | B67: LIMA | C67: 4.53 | D67: (M) .CO | E67: Exchange Online (Plan 1) | F67: 72530565 | G67: hugo.pineda@grupoconectar.co | H67: Hugo Antolin Pineda Rachumi (Raul Villanueva) | I67: =VLOOKUP(F67,'PLANTA PERU'!A:AL,2,0) -> PINEDA RACHUMI HUGO ANTOLIN | J67: =VLOOKUP(F67,'PLANTA PERU'!A:AL,10,0) -> BACK OFFICE | K67: IGUL | L67: =VLOOKUP(F67,'PLANTA PERU'!A:AD,7,0) -> 0 | M67: NA | N67: =VLOOKUP(F67,'PLANTA PERU'!A:AD,12,0) -> TERMINO FIJO | O67: HNFM | P67: HUAWEI PERU | Q67: NA | R67: NA | S67: NA | T67: TELECOMUNICACIONES SAC | U67: NA | V67: NA
A68: 45343 | B68: LIMA | C68: 4.53 | D68: (M) .CO | E68: Exchange Online (Plan 1) | F68: 75544027 | G68: jose.escobedo@grupoconectar.co | H68: Jose Escobedo Cardenas (Raul Villanueva) | I68: =VLOOKUP(F68,'PLANTA PERU'!A:AL,2,0) -> ESCOBEDO CARDENAS JOSE HUMBERTO | J68: =VLOOKUP(F68,'PLANTA PERU'!A:AL,10,0) -> BACK OFFICE | K68: IGUL | L68: =VLOOKUP(F68,'PLANTA PERU'!A:AD,7,0) -> 0 | M68: NA | N68: =VLOOKUP(F68,'PLANTA PERU'!A:AD,12,0) -> TERMINO FIJO | O68: HNFM | P68: HUAWEI PERU | Q68: NA | R68: NA | S68: NA | T68: TELECOMUNICACIONES SAC | U68: NA | V68: NA
A69: 45119 | B69: LIMA | C69: 4.53 | D69: (M) .CO | E69: Exchange Online (Plan 1) | F69: 46933538 | G69: edson.campos@grupoconectar.co | H69: EDSON MANUEL CAMPOS CHERO | I69: =VLOOKUP(F69,'PLANTA PERU'!A:AL,2,0) -> CAMPOS CHERO EDSON MANUEL | J69: =VLOOKUP(F69,'PLANTA PERU'!A:AL,10,0) -> SUPERVISOR FLM ENTEL | K69: IGUL | L69: =VLOOKUP(F69,'PLANTA PERU'!A:AD,7,0) -> 0 | M69: NA | N69: =VLOOKUP(F69,'PLANTA PERU'!A:AD,12,0) -> 0 | O69: MSIM | P69: CLARO PERU | Q69: NA | R69: NA | S69: NA | T69: TELECOMUNICACIONES SAC | U69: NA | V69: NA
A70: 45348 | B70: LIMA | C70: 4.53 | D70: (M) .CO | E70: Exchange Online (Plan 1) | F70: 73013315 | G70: Cristhian.palomino@grupoconectar.co | H70: CRISTHIAN SMITH MARIO PALOMINO UNZUETA | I70: =VLOOKUP(F70,'PLANTA PERU'!A:AL,2,0) -> PALOMINO UNZUETA CRISTHIAN SMITH MARIO | J70: =VLOOKUP(F70,'PLANTA PERU'!A:AL,10,0) -> TECNICO JUNIOR | K70: IGUL | L70: =VLOOKUP(F70,'PLANTA PERU'!A:AD,7,0) -> 0 | M70: NA | N70: =VLOOKUP(F70,'PLANTA PERU'!A:AD,12,0) -> TERMINO FIJO | O70: HNFM | P70: HUAWEI PERU | Q70: NA | R70: NA | S70: NA | T70: TELECOMUNICACIONES SAC | U70: NA | V70: NA
A71: 45352 | B71: LIMA | C71: 4.53 | D71: (M) .CO | E71: Exchange Online (Plan 1) | F71: 71267193 | G71: anderson.alvis@grupoconectar.co | H71: Anderson Alvis Abisrror | I71: =VLOOKUP(F71,'PLANTA PERU'!A:AL,2,0) -> ALVIS ABISRROR ANDERSON | J71: =VLOOKUP(F71,'PLANTA PERU'!A:AL,10,0) -> TECNICO JUNIOR MOTORIZADO TDP | K71: IGUL | L71: =VLOOKUP(F71,'PLANTA PERU'!A:AD,7,0) -> 0 | M71: NA | N71: =VLOOKUP(F71,'PLANTA PERU'!A:AD,12,0) -> INDEFINIDO | O71: HNFM | P71: HUAWEI PERU | Q71: NA | R71: NA | S71: NA | T71: TELECOMUNICACIONES SAC | U71: NA | V71: NA
...

Sheet PLANTA PERU
A1: CEDULA | B1: APELLIDOS Y NOMBRES | C1: EMP | D1: INGRESO | E1: VENCE | F1: EST | G1: RETIRO | H1: MOTIVO RETIRO | I1: MOTIVO RETIRO - ESPECIFICADO | J1: CARGO | K1: TIPO CARGO | L1: TIPO CONTRATO | M1: SUBPROCESO | N1: PROCESO | O1: CLIENTE | P1: CARPETA | Q1: PROYECTO | R1: LINEA N | S1: CIUDAD OPE | T1: REGIONAL | U1: AUSENT. GEN | V1: AUSENT. DM | W1: DIAS ACCID | X1: ROTACION | Y1: CC SUPERVISOR | Z1: NOMBRE SUPERVISOR | AA1: OBSERVACIONES | AB1: INGENIERIA | AC1: TOTAL VACACIONES ACUMULADOS | AD1: VACACIONES TOMADOS | AE1: VACACIONES PENDIENTES | AF1: TIPO DE CONTRATO | AG1: REEMBOLSO DE ESSALUD | AH1: SALARIO BASICO | AI1: REGIMEN | AJ1: CLASE CARGO | AK1: NIVEL CARGO | AL1: C.COSTO
A2: 46352583 | B2: ALATA DAVILA MICHAEL ALFREDO | C2: CP | D2: 45702 | E2: 46446 | F2: A | J2: TECNICO JUNIOR | K2: ADMTIVO | L2: INDEFINIDO | M2: TALENTO-GENERAL | N2: TALENTO HUMANO | O2: HUAWEI PERU | P2: FLM | Q2: NUEVOS NEG | R2: MOVIL | S2: LIMA | T2: PERU | U2: 0 | V2: 0 | X2: PLANTA | Y2: 43688420 | Z2: MIRANDA SUAREZ ANTENOR | AA2: ACTIVO TRABAJANDO | AB2: CERTIFICADO EN CLARO | AC2: 202.58333 | AD2: 181 | AE2: 21.583333 | AF2: INDEFINIDO | AH2: 2000 | AI2: GENERAL | AJ2: ADMINISTRATIVO | AK2: SUPERVISORES | AL2: HUAWEI FLM CLARO
A3: 70390056 | B3: ALFARO RODRIGUEZ JEANCARLOS DAVID EDEY | C3: CP | D3: 45306 | E3: 46446 | F3: A | J3: TECNICO ESPECIALISTA | K3: OPE UPC | L3: INDEFINIDO | M3: INGENIERIA-GENERAL | N3: INGENIERIA | O3: HUAWEI PERU | P3: FLM | Q3: NUEVOS NEG | R3: MOVIL | S3: LIMA | T3: PERU | U3: 0 | V3: 0 | X3: PLANTA | Y3: 3017373 | Z3: ROJAS PADILLA CESAR HUMBERTO | AA3: ACTIVO TRABAJANDO | AB3: NO APLICA | AC3: 201.83333 | AD3: 190 | AE3: 11.833333 | AF3: INDEFINIDO | AH3: 1300 | AI3: GENERAL | AJ3: OPERATIVO | AK3: TECNICOS | AL3: HUAWEI FLM TDP
A4: 10074429 | B4: ALLCCA CARRASCO MARCO ANTONIO | C4: CP | D4: 45880 | E4: 46446 | F4: A | J4: TECNICO ESPECIALISTA BASICO | K4: ADM OPE | L4: INDEFINIDO | M4: CONTROLLER-LIQUIDACION | N4: INGENIERIA | O4: HUAWEI PERU | P4: FLM | Q4: NUEVOS NEG | R4: MOVIL | S4: LIMA | T4: PERU | U4: 0 | V4: 0 | X4: PLANTA | Y4: 72810172 | Z4: MUÑOZ PIZARRO WILLIAM MARTIN | AA4: ACTIVO TRABAJANDO | AC4: 201.41667 | AD4: 175 | AE4: 26.416667 | AF4: INDEFINIDO | AH4: 1300 | AI4: GENERAL | AJ4: ADMINISTRATIVO | AK4: ANALISTAS | AL4: HUAWEI FLM TDP
A5: 8050213 | B5: ALONSO GARRIAZO HERNAN | C5: CP | D5: 46054 | E5: 46446 | F5: A | J5: TECNICO RESIDENTE | K5: APOYO UPC | L5: INDEFINIDO | M5: INGENIERIA-GENERAL | N5: INGENIERIA | O5: WIN OPERACIONES | P5: OYM | Q5: SOLU FIJAS | R5: MASIVAS | S5: LIMA | T5: PERU | U5: 0 | V5: 0 | X5: PLANTA | Y5: 4718074 | Z5: PORRAS TIBATA CARLOS MAURICIO | AA5: ACTIVO TRABAJANDO | AC5: 191.67123 | AD5: 160 | AE5: 31.671233 | AF5: INDEFINIDO | AH5: 2200 | AI5: GENERAL | AJ5: ADMINISTRATIVO | AK5: COORDINADORES | AL5: WIN OPERACIONES
A6: 40946309 | B6: ALVARADO VARGAS JOSE MANUEL | C6: CP | D6: 46054 | E6: 46446 | F6: A | J6: TECNICO RESIDENTE | K6: PER APOYO | L6: INDEFINIDO | M6: ABASTECIMIENTO-MATERIALES | N6: ABASTECIMIENTO | O6: HUAWEI PERU | P6: FLM | Q6: NUEVOS NEG | R6: MOVIL | S6: LIMA | T6: PERU | U6: 0 | V6: 0 | X6: PLANTA | Y6: 72566559 | Z6: SOTO CASTILLO JOSE ALEJANDRO | AA6: ACTIVO TRABAJANDO | AB6: CERTIFICADO EN CLARO | AC6: 188.71233 | AD6: 168 | AE6: 20.712329 | AF6: INDEFINIDO | AH6: 2000 | AI6: GENERAL | AJ6: CARGO UPC | AK6: SUPERVISORES | AL6: HUAWEI FLM TDP
A7: 71267193 | B7: ALVIS ABISRROR ANDERSON | C7: CP | D7: 46008 | E7: 46446 | F7: A | J7: TECNICO JUNIOR MOTORIZADO TDP | K7: ADM OPE | L7: INDEFINIDO | M7: INGENIERIA-GENERAL | N7: INGENIERIA | O7: WIN OPERACIONES | P7: OYM | Q7: SOLU FIJAS | R7: MASIVAS | S7: LIMA | T7: PERU | U7: 31 | V7: 31 | X7: PLANTA | Y7: 72810172 | Z7: MUÑOZ PIZARRO WILLIAM MARTIN | AA7: ACTIVO TRABAJANDO | AC7: 164.91667 | AD7: 120 | AE7: 44.916667 | AF7: TERMINO FIJO | AH7: 1300 | AI7: GENERAL | AJ7: ADMINISTRATIVO | AK7: SUPERVISORES | AL7: WIN OPERACIONES
A8: 41887361 | B8: ANAMPA GUTIERREZ IVAN WALDO | C8: CP | D8: 45497 | E8: 46446 | F8: A | J8: TECNICO JUNIOR | K8: ADMTIVO | L8: TERMINO FIJO | M8: CONTROLLER-LIQUIDACION | N8: INGENIERIA | O8: HUAWEI PERU | P8: FLM | Q8: NUEVOS NEG | R8: MOVIL | S8: LIMA | T8: PERU | U8: 0 | V8: 0 | X8: PLANTA | Y8: 72810172 | Z8: MUÑOZ PIZARRO WILLIAM MARTIN | AA8: ACTIVO TRABAJANDO | AC8: 89.236301 | AD8: 64 | AE8: 25.236301 | AF8: TERMINO FIJO | AH8: 1300 | AI8: GENERAL | AJ8: ADMINISTRATIVO | AK8: ANALISTAS | AL8: HUAWEI FLM LONG HAUL
A9: 70845087 | B9: ANGULO RAMOS RONALDO ESTHEFANO | C9: CP | D9: 45813 | E9: 46446 | F9: A | J9: AUXILIAR DE LIQUIDACION | K9: ADM UPC | L9: TERMINO FIJO | M9: ADMIN-GENERAL | N9: ADMINISTRACION | O9: MULTICLIENTE | P9: TRANSVERSAL | Q9: TRANSVERSAL | R9: INTEGRAL | S9: LIMA | T9: PERU | U9: 0 | V9: 0 | X9: PLANTA | Y9: 4718074 | Z9: PORRAS TIBATA CARLOS MAURICIO | AA9: ACTIVO TRABAJANDO | AB9: NO APLICA | AC9: 88.041667 | AD9: 47 | AE9: 41.041667 | AF9: TERMINO FIJO | AH9: 4000 | AI9: GENERAL | AJ9: ADMINISTRATIVO | AK9: JEFES | AL9: TRANSVERSAL
A10: 43096607 | B10: AQUINO BRAVO RONALD DIRSEO | C10: CP | D10: 45826 | E10: 46446 | F10: A | J10: SUPERVISOR MBB | K10: OPE UPC | L10: TERMINO FIJO | M10: TALENTO-SSTA | N10: SSTA | O10: HUAWEI PERU | P10: FLM | Q10: NUEVOS NEG | R10: MOVIL | S10: LIMA | T10: PERU | U10: 0 | V10: 0 | X10: PLANTA | Y10: 4718074 | Z10: PORRAS TIBATA CARLOS MAURICIO | AA10: ACTIVO TRABAJANDO | AB10: NO APLICA | AC10: 83.833333 | AD10: 52 | AE10: 31.833333 | AF10: TERMINO FIJO | AH10: 3500 | AI10: GENERAL | AJ10: CARGO UPC | AK10: COORDINADORES | AL10: HUAWEI FLM TDP
A11: 76007265 | B11: ARANDA URBANO CESAR JORDHI | C11: CP | D11: 46090 | E11: 46173 | F11: A | J11: TECNICO ESPECIALISTA | K11: OPE UPC | L11: TERMINO FIJO | M11: INGENIERIA-GENERAL | N11: INGENIERIA | O11: HUAWEI PERU | P11: FLM | Q11: NUEVOS NEG | R11: MOVIL | S11: LIMA | T11: PERU | U11: 11 | V11: 11 | X11: PLANTA | Y11: 10551431 | Z11: ESPINOZA BUSTAMANTE LUIS ABELARDO | AA11: ACTIVO TRABAJANDO | AB11: NO APLICA | AC11: 72 | AD11: 33 | AE11: 39 | AF11: TERMINO FIJO | AH11: 2200 | AI11: GENERAL | AJ11: OPERATIVO | AK11: TECNICOS | AL11: HUAWEI FLM CLARO
A12: 74588571 | B12: AROSEMENA DIAZ MATTHYUS AARON | C12: CP | D12: 46122 | E12: 46356 | F12: A | J12: TECNICO JUNIOR TDP | K12: ADMTIVO | L12: TERMINO FIJO | M12: INGENIERIA-GENERAL | N12: INGENIERIA | O12: HUAWEI PERU | P12: FLM | Q12: NUEVOS NEG | R12: MOVIL | S12: LIMA | T12: PERU | U12: 0 | V12: 0 | X12: PLANTA | Y12: 10551431 | Z12: ESPINOZA BUSTAMANTE LUIS ABELARDO | AA12: ACTIVO TRABAJANDO | AB12: NO APLICA | AC12: 71.416667 | AD12: 68 | AE12: 3.4166667 | AF12: TERMINO FIJO | AH12: 2400 | AI12: GENERAL | AJ12: OPERATIVO | AK12: TECNICOS | AL12: HUAWEI FLM CLARO
A13: 10642561 | B13: AVALOS ALARCON CRISTHIAN DANGELO | C13: CP | D13: 45922 | E13: 46356 | F13: A | J13: TECNICO ESPECIALISTA | K13: OPE UPC | L13: TERMINO FIJO | M13: INGENIERIA-GENERAL | N13: INGENIERIA | O13: HUAWEI PERU | P13: FLM | Q13: NUEVOS NEG | R13: MOVIL | S13: LIMA | T13: PERU | U13: 0 | V13: 0 | X13: PLANTA | Y13: 10551431 | Z13: ESPINOZA BUSTAMANTE LUIS ABELARDO | AA13: ACTIVO TRABAJANDO | AB13: NO APLICA | AC13: 71.416667 | AD13: 22 | AE13: 49.416667 | AF13: TERMINO FIJO | AH13: 2000 | AI13: GENERAL | AJ13: OPERATIVO | AK13: TECNICOS | AL13: HUAWEI FLM CLARO
A14: 45990537 | B14: BECERRA SOTO SANDRO JOHAN | C14: CP | D14: 45352 | E14: 46446 | F14: A | J14: TECNICO RESIDENTE TDP | K14: ADM UPC | L14: TERMINO FIJO | M14: INGENIERIA-GENERAL | N14: INGENIERIA | O14: HUAWEI PERU | P14: OLT | Q14: NUEVOS NEG | R14: INTEGRAL | S14: LIMA | T14: PERU | U14: 0 | V14: 0 | X14: PLANTA | Y14: 46151732 | Z14: LOPEZ UCHUYA KATHERINE WENDY | AA14: ACTIVO TRABAJANDO | AB14: NO APLICA | AC14: 71.25 | AD14: 23 | AE14: 48.25 | AF14: TERMINO FIJO | AH14: 1800 | AI14: GENERAL | AJ14: ADMINISTRATIVO | AK14: ANALISTAS | AL14: PROYECTO OLT
A15: 74199665 | B15: BELLIDO PUCHURI JONATHAN ELIAS | C15: CP | D15: 45337 | E15: 46356 | F15: A | J15: TECNICO ESPECIALISTA SENIOR | K15: ADM UPC | L15: TERMINO FIJO | M15: INGENIERIA-GENERAL | N15: INGENIERIA | O15: HUAWEI PERU | P15: FLM | Q15: NUEVOS NEG | R15: MOVIL | S15: LIMA | T15: PERU | U15: 0 | V15: 0 | X15: PLANTA | Y15: 10551431 | Z15: ESPINOZA BUSTAMANTE LUIS ABELARDO | AA15: ACTIVO TRABAJANDO | AB15: NO APLICA | AC15: 71 | AD15: 24 | AE15: 47 | AF15: TERMINO FIJO | AH15: 2500 | AI15: GENERAL | AJ15: OPERATIVO | AK15: TECNICOS | AL15: HUAWEI FLM CLARO
A16: 41444629 | B16: BENITES DIAZ ELVA MARIA DEL SOCOR | C16: CP | D16: 46037 | E16: 46203 | F16: A | J16: CONTADOR GENERAL | K16: ADMTIVO | L16: TERMINO FIJO | M16: CONTROLLER-LIQUIDACION | N16: CONTROLLER | O16: HUAWEI PERU | P16: FLM | Q16: NUEVOS NEG | R16: MOVIL | S16: LIMA | T16: PERU | U16: 1 | V16: 1 | X16: PLANTA | Y16: 46151732 | Z16: LOPEZ UCHUYA KATHERINE WENDY | AA16: ACTIVO TRABAJANDO | AB16: NO APLICA | AC16: 70.416667 | AD16: 41 | AE16: 29.416667 | AF16: TERMINO FIJO | AH16: 3000 | AI16: GENERAL | AJ16: CARGO UPC | AK16: ANALISTAS | AL16: HUAWEI FLM CLARO
A17: 75373817 | B17: BERNAL CANALES LEONIDAS MITCHEL | C17: CP | D17: 45974 | E17: 46446 | F17: A | J17: TECNICO JUNIOR MOTORIZADO TDP | K17: OPE UPC | L17: TERMINO FIJO | M17: TALENTO-SSTA | N17: SSTA | O17: HUAWEI PERU | P17: FLM | Q17: NUEVOS NEG | R17: MOVIL | S17: LIMA | T17: PERU | U17: 0 | V17: 0 | X17: PLANTA | Y17: 9302925 | Z17: MOLINA VILA EDWIN MANUEL | AA17: ACTIVO TRABAJANDO | AB17: NO APLICA | AC17: 67.833333 | AD17: 26 | AE17: 41.833333 | AF17: TERMINO FIJO | AH17: 2000 | AI17: GENERAL | AJ17: CARGO UPC | AK17: ANALISTAS | AL17: HUAWEI FLM CLARO
A18: 76297793 | B18: BERROSPI CHAUPIS IVAN RODRIGO | C18: CP | D18: 46132 | E18: 46446 | F18: A | J18: ANALISTA FINANCIERO | K18: ADM UPC | L18: INDEFINIDO | M18: CONTEL PE-GENERAL | N18: GERENCIA CONTEL PE | O18: MULTICLIENTE | P18: TRANSVERSAL | Q18: TRANSVERSAL | R18: INTEGRAL | S18: LIMA | T18: PERU | U18: 0 | V18: 0 | X18: PLANTA | AA18: ACTIVO TRABAJANDO | AB18: NO APLICA | AC18: 75.083333 | AD18: 17 | AE18: 58.083333 | AF18: INDEFINIDO | AH18: 15943.2 | AI18: GENERAL | AJ18: ADMINISTRATIVO | AK18: GERENTES | AL18: TRANSVERSAL
A19: 42778138 | B19: BOZA PARIONA JORGE LUIS | C19: CP | D19: 45931 | E19: 46265 | F19: A | J19: TECNICO RESIDENTE TDP | K19: OPE UPC | L19: TERMINO FIJO | M19: INGENIERIA-GENERAL | N19: INGENIERIA | O19: HUAWEI PERU | P19: FLM | Q19: NUEVOS NEG | R19: MOVIL | S19: LIMA | T19: PERU | U19: 0 | V19: 0 | X19: PLANTA | Y19: 10551431 | Z19: ESPINOZA BUSTAMANTE LUIS ABELARDO | AA19: ACTIVO TRABAJANDO | AB19: NO APLICA | AC19: 64.664384 | AD19: 15 | AE19: 49.664384 | AF19: TERMINO FIJO | AH19: 1900 | AI19: GENERAL | AJ19: OPERATIVO | AK19: TECNICOS | AL19: HUAWEI FLM LONG HAUL
A20: 42712391 | B20: BRAVO VIVANCO JUAN CARLOS | C20: CP | D20: 46125 | E20: 46265 | F20: A | J20: BACK OFFICE | K20: OPE UPC | L20: TERMINO FIJO | M20: INGENIERIA-GENERAL | N20: INGENIERIA | O20: HUAWEI PERU | P20: FLM | Q20: NUEVOS NEG | R20: MOVIL | S20: LIMA | T20: PERU | U20: 0 | V20: 0 | X20: PLANTA | Y20: 10551431 | Z20: ESPINOZA BUSTAMANTE LUIS ABELARDO | AA20: ACTIVO TRABAJANDO | AB20: NO APLICA | AC20: 64.178082 | AD20: 34 | AE20: 30.178082 | AF20: TERMINO FIJO | AH20: 2200 | AI20: GENERAL | AJ20: OPERATIVO | AK20: TECNICOS | AL20: HUAWEI FLM CLARO
A21: 80524414 | B21: BRIZUELA CORRALES JORGE ARTURO | C21: CP | D21: 45782 | E21: 46265 | F21: A | J21: AUXILIAR SERVICIOS GENERALES | K21: ADM UPC | L21: TERMINO FIJO | M21: ABASTECIMIENTO-MATERIALES | N21: ABASTECIMIENTO | O21: HUAWEI PERU | P21: OYM | Q21: NUEVOS NEG | R21: MOVIL | S21: LIMA | T21: PERU | U21: 0 | V21: 0 | X21: PLANTA | Y21: 41444629 | Z21: BENITES DIAZ ELVA MARIA DEL SOCORRO | AA21: ACTIVO TRABAJANDO | AB21: NO APLICA | AC21: 63.244863 | AD21: 15 | AE21: 48.244863 | AF21: TERMINO FIJO | AH21: 2200 | AI21: GENERAL | AJ21: CARGO UPC | AK21: ANALISTAS | AL21: HUAWEI FLM CLARO
A22: 71452551 | B22: CABREJOS MONTENEGRO CESAR ABEL | C22: CP | D22: 45352 | E22: 46356 | F22: A | J22: TECNICO RESIDENTE TDP | K22: OPE UPC | L22: TERMINO FIJO | M22: INGENIERIA-GENERAL | N22: INGENIERIA | O22: HUAWEI PERU | P22: FLM | Q22: NUEVOS NEG | R22: MOVIL | S22: LIMA | T22: PERU | U22: 0 | V22: 0 | X22: PLANTA | Y22: 3017373 | Z22: ROJAS PADILLA CESAR HUMBERTO | AA22: ACTIVO TRABAJANDO | AB22: NO APLICA | AC22: 35.21347 | AD22: 43 | AE22: -7.7865297 | AF22: TERMINO FIJO | AH22: 2000 | AI22: GENERAL | AJ22: OPERATIVO | AK22: TECNICOS | AL22: HUAWEI FLM TDP
A23: 40597379 | B23: CABRERA TAPIA EDGAR | C23: CP | D23: 45352 | E23: 46265 | F23: A | J23: TECNICO RESIDENTE TDP | K23: OPE UPC | L23: TERMINO FIJO | M23: INGENIERIA-GENERAL | N23: INGENIERIA | O23: HUAWEI PERU | P23: FLM | Q23: NUEVOS NEG | R23: MOVIL | S23: LIMA | T23: PERU | U23: 0 | V23: 0 | X23: PLANTA | Y23: 43096607 | Z23: AQUINO BRAVO RONALD DIRSEO | AA23: ACTIVO TRABAJANDO | AB23: NO APLICA | AC23: 35.21347 | AD23: 22 | AE23: 13.21347 | AF23: TERMINO FIJO | AH23: 2000 | AI23: GENERAL | AJ23: OPERATIVO | AK23: TECNICOS | AL23: HUAWEI FLM TDP
A24: 71279121 | B24: CAMPOS PE?A JAIME MANUEL | C24: CP | D24: 46017 | E24: 46446 | F24: A | J24: TECNICO JUNIOR | K24: OPE UPC | L24: TERMINO FIJO | M24: CONTROLLER-LIQUIDACION | N24: CONTROLLER | O24: HUAWEI PERU | P24: MBB | Q24: NUEVOS NEG | R24: MOVIL | S24: LIMA | T24: PERU | U24: 2 | V24: 2 | X24: PLANTA | Y24: 46151732 | Z24: LOPEZ UCHUYA KATHERINE WENDY | AA24: ACTIVO TRABAJANDO | AC24: 62.718037 | AD24: 22 | AE24: 40.718037 | AF24: TERMINO FIJO | AH24: 2000 | AI24: GENERAL | AJ24: CARGO UPC | AK24: ANALISTAS | AL24: HUAWEI MBB
A25: 74569469 | B25: CARHUAJULCA LEVANO JUAN GABRIEL | C25: CP | D25: 45384 | E25: 46265 | F25: A | J25: TECNICO ESPECIALISTA TDP | K25: OPE UPC | L25: TERMINO FIJO | M25: INGENIERIA-GENERAL | N25: INGENIERIA | O25: HUAWEI PERU | P25: FLM | Q25: NUEVOS NEG | R25: MOVIL | S25: LIMA | T25: PERU | U25: 11 | V25: 10 | X25: PLANTA | Y25: 3017373 | Z25: ROJAS PADILLA CESAR HUMBERTO | AA25: ACTIVO TRABAJANDO | AB25: NO APLICA | AC25: 34.646119 | AD25: 31 | AE25: 3.6461187 | AF25: TERMINO FIJO | AH25: 2000 | AI25: GENERAL | AJ25: OPERATIVO | AK25: TECNICOS | AL25: HUAWEI FLM TDP
A26: 42785003 | B26: CARRASCO VILCA FRANK | C26: CP | D26: 46054 | E26: 46356 | F26: A | J26: INGENIERO RESIDENTE | K26: OPE UPC | L26: TERMINO FIJO | M26: INGENIERIA-GENERAL | N26: INGENIERIA | O26: HUAWEI PERU | P26: FLM | Q26: NUEVOS NEG | R26: MOVIL | S26: LIMA | T26: PERU | U26: 0 | V26: 0 | X26: PLANTA | Y26: 10551431 | Z26: ESPINOZA BUSTAMANTE LUIS ABELARDO | AA26: ACTIVO TRABAJANDO | AB26: NO APLICA | AC26: 62.312785 | AD26: 38 | AE26: 24.312785 | AF26: TERMINO FIJO | AH26: 1700 | AI26: GENERAL | AJ26: OPERATIVO | AK26: TECNICOS | AL26: HUAWEI FLM CLARO
A27: 75415990 | B27: CASTILLO MARCHENA YELSIN DENILSON | C27: CP | D27: 46056 | E27: 46265 | F27: A | J27: TECNICO ESPECIALISTA JUNIOR | K27: OPE UPC | L27: TERMINO FIJO | M27: INGENIERIA-GENERAL | N27: INGENIERIA | O27: HUAWEI PERU | P27: FLM | Q27: NUEVOS NEG | R27: MOVIL | S27: LIMA | T27: PERU | U27: 0 | V27: 0 | X27: PLANTA | AA27: ACTIVO TRABAJANDO | AB27: NO APLICA | AC27: 34.646119 | AD27: 15 | AE27: 19.646119 | AF27: TERMINO FIJO | AH27: 2000 | AI27: GENERAL | AJ27: OPERATIVO | AK27: TECNICOS | AL27: HUAWEI FLM TDP
A28: 43960188 | B28: CASTILLO MARTINEZ PEDRO | C28: CP | D28: 45719 | E28: 46265 | F28: A | J28: TECNICO ESPECIALISTA | K28: OPE UPC | L28: TERMINO FIJO | M28: INGENIERIA-GENERAL | N28: INGENIERIA | O28: HUAWEI PERU | P28: FLM | Q28: NUEVOS NEG | R28: MOVIL | S28: LIMA | T28: PERU | U28: 0 | V28: 0 | X28: PLANTA | AA28: ACTIVO TRABAJANDO | AB28: NO APLICA | AC28: 34.646119 | AD28: 46 | AE28: -11.353881 | AF28: TERMINO FIJO | AH28: 2000 | AI28: GENERAL | AJ28: OPERATIVO | AK28: TECNICOS | AL28: HUAWEI FLM TDP
A29: 47960741 | B29: CASTRO GOMEZ CESAR ENRIQUE | C29: CP | D29: 46054 | E29: 46265 | F29: A | J29: TECNICO RESIDENTE | K29: OPE UPC | L29: TERMINO FIJO | M29: INGENIERIA-GENERAL | N29: INGENIERIA | O29: HUAWEI PERU | P29: FLM | Q29: NUEVOS NEG | R29: MOVIL | S29: LIMA | T29: PERU | U29: 0 | V29: 0 | X29: PLANTA | AA29: ACTIVO TRABAJANDO | AB29: NO APLICA | AC29: 34.646119 | AD29: 30 | AE29: 4.6461187 | AF29: TERMINO FIJO | AH29: 2000 | AI29: GENERAL | AJ29: OPERATIVO | AK29: TECNICOS | AL29: HUAWEI FLM TDP
A30: 9448420 | B30: CASTRO SALAZAR WALTER ORLANDO | C30: CP | D30: 45428 | E30: 46265 | F30: A | J30: TECNICO ESPECIALISTA TDP | K30: OPE UPC | L30: TERMINO FIJO | M30: INGENIERIA-GENERAL | N30: INGENIERIA | O30: HUAWEI PERU | P30: FLM | Q30: NUEVOS NEG | R30: MOVIL | S30: LIMA | T30: PERU | U30: 0 | V30: 0 | X30: PLANTA | AA30: ACTIVO TRABAJANDO | AB30: NO APLICA | AC30: 34.646119 | AD30: 30 | AE30: 4.6461187 | AF30: TERMINO FIJO | AH30: 2000 | AI30: GENERAL | AJ30: OPERATIVO | AK30: TECNICOS | AL30: HUAWEI FLM TDP
A31: 44285911 | B31: CAYCHO PACHECO MARIO MIGUEL | C31: CP | D31: 43875 | E31: 46265 | F31: A | J31: SUPERVISOR LOGISTICO | K31: OPE UPC | L31: TERMINO FIJO | M31: INGENIERIA-GENERAL | N31: INGENIERIA | O31: HUAWEI PERU | P31: FLM | Q31: NUEVOS NEG | R31: MOVIL | S31: LIMA | T31: PERU | U31: 0 | V31: 0 | X31: PLANTA | AA31: ACTIVO TRABAJANDO | AB31: NO APLICA | AC31: 34.646119 | AD31: 20 | AE31: 14.646119 | AF31: TERMINO FIJO | AH31: 2000 | AI31: GENERAL | AJ31: OPERATIVO | AK31: TECNICOS | AL31: HUAWEI FLM TDP
A32: 40658303 | B32: CERRON CAMAYO CARLOS PABLO | C32: CP | D32: 45364 | E32: 46265 | F32: A | J32: TECNICO ESPECIALISTA TDP | K32: OPE UPC | L32: TERMINO FIJO | M32: INGENIERIA-GENERAL | N32: INGENIERIA | O32: HUAWEI PERU | P32: FLM | Q32: NUEVOS NEG | R32: MOVIL | S32: LIMA | T32: PERU | U32: 0 | V32: 0 | X32: PLANTA | AA32: ACTIVO TRABAJANDO | AB32: NO APLICA | AC32: 34.646119 | AD32: 30 | AE32: 4.6461187 | AF32: TERMINO FIJO | AH32: 2000 | AI32: GENERAL | AJ32: OPERATIVO | AK32: TECNICOS | AL32: HUAWEI FLM TDP
A33: 48453046 | B33: CHAMANA YARLEQUE JULIO | C33: CP | D33: 46128 | E33: 46265 | F33: A | J33: TECNICO JUNIOR | K33: OPE UPC | L33: TERMINO FIJO | M33: INGENIERIA-GENERAL | N33: INGENIERIA | O33: HUAWEI PERU | P33: FLM | Q33: NUEVOS NEG | R33: MOVIL | S33: LIMA | T33: PERU | U33: 0 | V33: 0 | X33: PLANTA | AA33: ACTIVO TRABAJANDO | AB33: NO APLICA | AC33: 34.646119 | AD33: 31 | AE33: 3.6461187 | AF33: TERMINO FIJO | AH33: 2000 | AI33: GENERAL | AJ33: OPERATIVO | AK33: TECNICOS | AL33: HUAWEI FLM TDP
A34: 4927978 | B34: CHARMELO HERNANDEZ ADONIS ALDAIR | C34: CP | D34: 45790 | E34: 46265 | F34: A | J34: TECNICO JUNIOR | K34: OPE UPC | L34: TERMINO FIJO | M34: INGENIERIA-GENERAL | N34: INGENIERIA | O34: HUAWEI PERU | P34: FLM | Q34: NUEVOS NEG | R34: MOVIL | S34: LIMA | T34: PERU | U34: 0 | V34: 0 | X34: PLANTA | AA34: ACTIVO TRABAJANDO | AB34: NO APLICA | AC34: 34.646119 | AD34: 30 | AE34: 4.6461187 | AF34: TERMINO FIJO | AH34: 2000 | AI34: GENERAL | AJ34: OPERATIVO | AK34: TECNICOS | AL34: HUAWEI FLM TDP
A35: 41713199 | B35: CHAVEZ AGUEDO MARCO ANTONIO | C35: CP | D35: 46054 | E35: 46265 | F35: A | J35: TECNICO RESIDENTE | K35: OPE UPC | L35: TERMINO FIJO | M35: INGENIERIA-GENERAL | N35: INGENIERIA | O35: HUAWEI PERU | P35: FLM | Q35: NUEVOS NEG | R35: MOVIL | S35: LIMA | T35: PERU | U35: 0 | V35: 0 | X35: PLANTA | AA35: ACTIVO TRABAJANDO | AB35: NO APLICA | AC35: 34.646119 | AD35: 30 | AE35: 4.6461187 | AF35: TERMINO FIJO | AH35: 2000 | AI35: GENERAL | AJ35: OPERATIVO | AK35: TECNICOS | AL35: HUAWEI FLM TDP
A36: 76661104 | B36: CHAVEZ DELGADO SERGIO ARMANDO | C36: CP | D36: 45843 | E36: 46265 | F36: A | J36: TECNICO JUNIOR | K36: OPE UPC | L36: TERMINO FIJO | M36: INGENIERIA-GENERAL | N36: INGENIERIA | O36: HUAWEI PERU | P36: FLM | Q36: NUEVOS NEG | R36: MOVIL | S36: LIMA | T36: PERU | U36: 0 | V36: 0 | X36: PLANTA | AA36: ACTIVO TRABAJANDO | AB36: NO APLICA | AC36: 34.646119 | AD36: 16 | AE36: 18.646119 | AF36: TERMINO FIJO | AH36: 2700 | AI36: GENERAL | AJ36: OPERATIVO | AK36: TECNICOS | AL36: HUAWEI FLM TDP
A37: 46002701 | B37: CHAVEZ MONTENEGRO JEAN PIERRE | C37: CP | D37: 46087 | E37: 46265 | F37: A | J37: TECNICO 1 | K37: OPE UPC | L37: TERMINO FIJO | M37: INGENIERIA-GENERAL | N37: INGENIERIA | O37: HUAWEI PERU | P37: FLM | Q37: NUEVOS NEG | R37: MOVIL | S37: LIMA | T37: PERU | U37: 0 | V37: 0 | X37: PLANTA | AA37: ACTIVO TRABAJANDO | AB37: NO APLICA | AC37: 34.646119 | AD37: 38 | AE37: -3.3538813 | AF37: TERMINO FIJO | AH37: 2000 | AI37: GENERAL | AJ37: OPERATIVO | AK37: TECNICOS | AL37: HUAWEI FLM TDP
A38: 71490074 | B38: CHAVEZ PALOMINO ELIOT MARTIN | C38: CP | D38: 45141 | E38: 46265 | F38: A | J38: ANALISTA ADMINISTRATIVO | K38: OPE UPC | L38: TERMINO FIJO | M38: INGENIERIA-GENERAL | N38: INGENIERIA | O38: HUAWEI PERU | P38: FLM | Q38: NUEVOS NEG | R38: MOVIL | S38: LIMA | T38: PERU | U38: 0 | V38: 0 | X38: PLANTA | AA38: ACTIVO TRABAJANDO | AB38: NO APLICA | AC38: 34.646119 | AD38: 42 | AE38: -7.3538813 | AF38: TERMINO FIJO | AH38: 2000 | AI38: GENERAL | AJ38: OPERATIVO | AK38: TECNICOS | AL38: HUAWEI FLM TDP
... A40: 9598278 | B40: CHIRINOS SEVILLA LUIS ERNESTO | C40: CP | D40: 46113 | E40: 46265 | F40: A | J40: TECNICO RESIDENTE TDP | K40: OPE UPC | L40: TERMINO FIJO | M40: INGENIERIA-GENERAL | N40: INGENIERIA | O40: HUAWEI PERU | P40: FLM | Q40: NUEVOS NEG | R40: MOVIL | S40: LIMA | T40: PERU | U40: 0 | V40: 0 | X40: PLANTA | AA40: ACTIVO TRABAJANDO | AB40: NO APLICA | AC40: 34.569635 | AD40: 30 | AE40: 4.5696347 | AF40: TERMINO FIJO | AH40: 2000 | AI40: GENERAL | AJ40: OPERATIVO | AK40: TECNICOS | AL40: HUAWEI FLM TDP
A41: 47991206 | B41: CHUIMA SAU?E JOSE LUIS | C41: CP | D41: 46113 | E41: 46356 | F41: A | J41: BACK OFFICE | K41: ADMTIVO | L41: TERMINO FIJO | M41: INGENIERIA-GENERAL | N41: INGENIERIA | O41: HUAWEI PERU | P41: FLM | Q41: NUEVOS NEG | R41: MOVIL | S41: LIMA | T41: PERU | U41: 0 | V41: 0 | X41: PLANTA | Y41: 4718074 | Z41: PORRAS TIBATA CARLOS MAURICIO | AA41: ACTIVO TRABAJANDO | AB41: NO APLICA | AC41: 62.195776 | AD41: 40 | AE41: 22.195776 | AF41: TERMINO FIJO | AH41: 3000 | AI41: GENERAL | AJ41: CARGO UPC | AK41: COORDINADORES | AL41: HUAWEI FLM CLARO
...

Sheet NOVEDADES
A1: FECHA_CREACION | B1: CIUDAD LABOR | C1: PRECIO USD | D1: DOMINIO | E1: PLAN | F1: NUM_DOCUMENTO | G1: NOMBRE_USUARIO | H1: OBSERVACIÓN (Solicitante) | I1: APELLIDO NOMBRE | J1: CARGO | K1: CU1 | L1: CU1-PROCESO | M1: CU1-REGIONAL | N1: CU1-CIUDAD | O1: CU3 | P1: CU3-CLIENTE | Q1: CU3-LINEA DE NEGOCIO | R1: CU3-PROYECTO | S1: GRUPO | T1: EMPRESA | U1: PROCESO GEN | V1: % PROYECTO | W1: OBSERVACION | X1: Fecha Modificación
A2: 45630 | B2: BOGOTA | C2: 5.5 | D2: (M) .CO | E2: Microsoft 365 Empresa Básico | F2: 1193218651 | G2: juan.soto@grupoconectar.co | H2: (Yuliana Cardenas) | I2: NA | J2: NA | K2: NA | L2: NA | M2: NA | N2: NA | O2: NA | P2: NA | Q2: NA | R2: NA | S2: NA | T2: NA | U2: NA | V2: NA | W2: Cambio de Asignacion a Angelica Paez | X2: 45967
A3: 45680 | B3: BOGOTA | C3: 11.3 | D3: (M) .CO | E3: Microsoft 365 Empresa Estándar | F3: 1013692183 | G3: santiago.leon@grupoconectar.co | H3: LEON SALAMANCA SANTIAGO FELIPE (ana durán) | I3: NA | J3: NA | K3: NA | L3: NA | M3: NA | N3: NA | O3: NA | P3: NA | Q3: NA | R3: NA | S3: NA | T3: NA | U3: NA | V3: NA | W3: Cambio de Asignacion a Tania Estefany Castro | X3: 45967
A4: 45294 | B4: MEDELLIN | C4: 5.5 | D4: (M) .CO | E4: Microsoft 365 Empresa Básico | F4: 6104831 | G4: rodolfo.tumal@grupoconectar.co | H4: Hernandez Valencia Nelson Andres(Christofer) | I4: TUMAL JURADO RODOLFO | J4: COORDINADOR OPERACION FLM | K4: IGAM | L4: INGENIERIA-GENERAL | M4: REG ANTIO | N4: MEDELLIN | O4: HNAL | P4: HUAWEI | Q4: NUEVOS NEG | R4: FLM ALL IN ONE | S4: CLIENTES | T4: CONECTAR TV | U4: INGENIERIA | V4: OPERATIVO | W4: Cambio de Asignacion a Milton Fabian Pino | X4: 45967
A5: 45296 | B5: BOGOTA | C5: 11.3 | D5: (M) .CO | E5: Microsoft 365 Empresa Estándar | F5: 1000472275 | G5: maria.lozano@grupoconectar.co | H5: Maria Daniela Lozano Garcia(Randy) | I5: LOZANO GARCIA MARIA DANIELA | J5: ANALISTA TALENTO HUMANO | K5: TGCB | L5: TALENTO-GENERAL | M5: REG CENTRO | N5: BOGOTA | O5: ISST | P5: TIGO | Q5: SOLU FIJAS | R5: STRONG | S5: CSC | T5: CONECTAR TV | U5: TALENTO HUMANO | V5: OPERATIVO | W5: Cambio de Asignacion a Danna Valentina Forero Espinosa | X5: 45968
A6: 43931 | B6: BOGOTA | C6: 11.3 | D6: (M) .CO | E6: Microsoft 365 Empresa Estándar | F6: 1005248870 | G6: derly.fandino@grupoconectar.co | I6: FANDINO QUIROGA DERLY YADIANA | J6: ANALISTA RELACIONES LABORALES | K6: TWTN | L6: TALENTO-RELABO | M6: TRANSVERSAL | N6: NACIONAL | O6: TTTR | P6: TRANSV CTV | Q6: TRANSVER | R6: TRANSV UEN | S6: CSC | T6: CONECTAR TV | U6: TALENTO HUMANO | V6: ADMINISTRATIVO | W6: Cambio de Asignacion a Miley Portillo | X6: 45965
A7: 45468 | B7: CALI | C7: 4.53 | D7: (M) .CO | E7: Exchange Online (Plan 1) | F7: 1144107409 | G7: valeria.oliva@grupoconectar.co | H7: R3 (RANDY AGUILAR) | I7: OLIVA SOLARTE VALERIA | J7: BACKOFFICE OPERACION | K7: IGVI | L7: INGENIERIA-GENERAL | M7: REG VALLE | N7: CALI | O7: CSIM | P7: CLARO R3 | Q7: SOLU FIJAS | R7: IMM | S7: CLIENTES | T7: CONECTAR TV | U7: INGENIERIA | V7: PERSONAL APOYO | W7: Cambio a Licencia estándar | X7: 45965
A8: 45343 | B8: IBAGUE | C8: 5.5 | D8: (M) .CO | E8: Microsoft 365 Empresa Básico | F8: 1005815440 | G8: maria.rodriguez@grupoconectar.co | H8: MARIA CAMUA RODRIGUEZ LOZANO (Evelin) | I8: NA | J8: NA | K8: NA | L8: NA | M8: NA | N8: NA | O8: NA | P8: NA | Q8: NA | R8: NA | S8: NA | T8: NA | U8: NA | V8: NA | W8: Cambio de Asignacion a Laura Balaguera | X8: 45968
A9: 45387 | B9: IBAGUE | C9: 11.3 | D9: (M) .CO | E9: Microsoft 365 Empresa Estándar | F9: 93386747 | G9: Ernesto.acosta@grupoconectar.co | H9: Hugo Ernesto Acosta Alvarez (Nicolás Pulgarín CLARO R3) | I9: ACOSTA ALVAREZ HUGO ERNESTO | J9: ANALISTA LOGISTICO | K9: SGVI | L9: DISAN-GENERAL | M9: REG VALLE | N9: CALI | O9: TTTR | P9: TRANSV CTV | Q9: TRANSVER | R9: TRANSV UEN | S9: DISAN | T9: CONECTAR TV | U9: DISAN | V9: OTROS | W9: Cambio de Asignación a María Zuluaga | X9: 45968
A10: 45532 | B10: BOGOTA | C10: 5.5 | D10: (M) .CO | E10: Microsoft 365 Empresa Básico | F10: 79784200 | G10: desarrollo.proyectos@grupoconectar.co | H10: usuario para desarrollo Proyectos | I10: =IFERROR(VLOOKUP($F10,MatrizHDUniclass!$A:$AN,3,0),"NA") -> PENA CLAVIJO LUIS EDUARDO | J10: =IFERROR(VLOOKUP($F10,MatrizHDUniclass!$A:$AN,19,0),"NA") -> GERENTE CONTROLLER | K10: =IFERROR(VLOOKUP($F10,MatrizHDUniclass!$A:$AN,24,0),"NA") -> BGTN | L10: =IFERROR(VLOOKUP($F10,MatrizHDUniclass!$A:$AN,31,0),"NA") -> CONTROLLER-GENERAL | M10: =IFERROR(VLOOKUP($F10,MatrizHDUniclass!$A:$AN,32,0),"NA") -> TRANSVERSAL | N10: =IFERROR(VLOOKUP($F10,MatrizHDUniclass!$A:$AN,33,0),"NA") -> NACIONAL | O10: =IFERROR(VLOOKUP($F10,MatrizHDUniclass!$A:$AN,26,0),"NA") -> LTTR | P10: =IFERROR(VLOOKUP($F10,MatrizHDUniclass!$A:$AN,34,0),"NA") -> CASA MATRIZ | Q10: =IFERROR(VLOOKUP($F10,MatrizHDUniclass!$A:$AN,35,0),"NA") -> TRANSVER | R10: =IFERROR(VLOOKUP($F10,MatrizHDUniclass!$A:$AN,36,0),"NA") -> TRANSV UEN | S10: =IFERROR(VLOOKUP($F10,MatrizHDUniclass!$A:$AN,37,0),"NA") -> CONTROLLER | T10: =IFERROR(VLOOKUP($F10,MatrizHDUniclass!$A:$AN,38,0),"NA") -> INVESTMENT | U10: =IFERROR(VLOOKUP($F10,MatrizHDUniclass!$A:$AN,39,0),"NA") -> CONTROLLER | V10: =IFERROR(VLOOKUP($F10,MatrizHDUniclass!$A:$AN,40,0),"NA") -> ADMINISTRATIVO | W10: Asignación de Licencia a Javier Gaitan | X10: 45972
A11: 44742 | B11: MEDELLIN | C11: 5.5 | D11: (M) .CO | E11: Microsoft 365 Empresa Básico | F11: 1073327029 | G11: cesar.osorio.u@grupoconectar.co | H11: (Crhistofer García) | I11: OSORIO ULLOA CESAR DARIO | J11: COORDINADOR OPERACION FLM | K11: IGAM | L11: INGENIERIA-GENERAL | M11: REG ANTIO | N11: MEDELLIN | O11: HNAL | P11: HUAWEI | Q11: NUEVOS NEG | R11: FLM ALL IN ONE | S11: CLIENTES | T11: CONECTAR TV | U11: INGENIERIA | V11: OPERATIVO | W11: Cambio de Asignación a Wilton Avedaño | X11: 45972
A12: 44008 | B12: MEDELLIN | C12: 5.5 | D12: (M) .CO | E12: Microsoft 365 Empresa Básico | F12: 1152693429 | G12: katerin.ruiz@grupoconectar.co | H12: RUIZ ALVAREZ KATERIN ANDREA | I12: =IFERROR(VLOOKUP($F12,MatrizHDUniclass!$A:$AN,3,0),"NA") -> NA | J12: =IFERROR(VLOOKUP($F12,MatrizHDUniclass!$A:$AN,19,0),"NA") -> NA | K12: =IFERROR(VLOOKUP($F12,MatrizHDUniclass!$A:$AN,24,0),"NA") -> NA | L12: =IFERROR(VLOOKUP($F12,MatrizHDUniclass!$A:$AN,31,0),"NA") -> NA | M12: =IFERROR(VLOOKUP($F12,MatrizHDUniclass!$A:$AN,32,0),"NA") -> NA | N12: =IFERROR(VLOOKUP($F12,MatrizHDUniclass!$A:$AN,33,0),"NA") -> NA | O12: =IFERROR(VLOOKUP($F12,MatrizHDUniclass!$A:$AN,26,0),"NA") -> NA | P12: =IFERROR(VLOOKUP($F12,MatrizHDUniclass!$A:$AN,34,0),"NA") -> NA | Q12: =IFERROR(VLOOKUP($F12,MatrizHDUniclass!$A:$AN,35,0),"NA") -> NA | R12: =IFERROR(VLOOKUP($F12,MatrizHDUniclass!$A:$AN,36,0),"NA") -> NA | S12: =IFERROR(VLOOKUP($F12,MatrizHDUniclass!$A:$AN,37,0),"NA") -> NA | T12: =IFERROR(VLOOKUP($F12,MatrizHDUniclass!$A:$AN,38,0),"NA") -> NA | U12: =IFERROR(VLOOKUP($F12,MatrizHDUniclass!$A:$AN,39,0),"NA") -> NA | V12: =IFERROR(VLOOKUP($F12,MatrizHDUniclass!$A:$AN,40,0),"NA") -> NA | W12: Cambio de Asignación a Cindy Vargas | X12: 45972
A13: 44201 | B13: MEDELLIN | C13: 5.5 | D13: (M) .CO | E13: Microsoft 365 Empresa Básico | F13: 1003069083 | G13: ader.avila@grupoconectar.co | H13: (Juan Guarín) | I13: NA | J13: NA | K13: NA | L13: NA | M13: NA | N13: NA | O13: NA | P13: NA | Q13: NA | R13: NA | S13: NA | T13: NA | U13: NA | V13: NA | W13: Cambio de Asignación a Jose García | X13: 45972
A14: 45241 | B14: CALI | C14: 11.3 | D14: (M) .CO | E14: Microsoft 365 Empresa Estándar | F14: 1144193545 | G14: sebastian.barragan@grupoconectar.co | H14: SEBASTIAN STEVEN BARRAGAN CUERO R3( Eliesid González) | I14: =IFERROR(VLOOKUP($F14,MatrizHDUniclass!$A:$AN,3,0),"NA") -> NA | J14: =IFERROR(VLOOKUP($F14,MatrizHDUniclass!$A:$AN,19,0),"NA") -> NA | K14: =IFERROR(VLOOKUP($F14,MatrizHDUniclass!$A:$AN,24,0),"NA") -> NA | L14: =IFERROR(VLOOKUP($F14,MatrizHDUniclass!$A:$AN,31,0),"NA") -> NA | M14: =IFERROR(VLOOKUP($F14,MatrizHDUniclass!$A:$AN,32,0),"NA") -> NA | N14: =IFERROR(VLOOKUP($F14,MatrizHDUniclass!$A:$AN,33,0),"NA") -> NA | O14: =IFERROR(VLOOKUP($F14,MatrizHDUniclass!$A:$AN,26,0),"NA") -> NA | P14: =IFERROR(VLOOKUP($F14,MatrizHDUniclass!$A:$AN,34,0),"NA") -> NA | Q14: =IFERROR(VLOOKUP($F14,MatrizHDUniclass!$A:$AN,35,0),"NA") -> NA | R14: =IFERROR(VLOOKUP($F14,MatrizHDUniclass!$A:$AN,36,0),"NA") -> NA | S14: =IFERROR(VLOOKUP($F14,MatrizHDUniclass!$A:$AN,37,0),"NA") -> NA | T14: =IFERROR(VLOOKUP($F14,MatrizHDUniclass!$A:$AN,38,0),"NA") -> NA | U14: =IFERROR(VLOOKUP($F14,MatrizHDUniclass!$A:$AN,39,0),"NA") -> NA | V14: =IFERROR(VLOOKUP($F14,MatrizHDUniclass!$A:$AN,40,0),"NA") -> NA | W14: Eliminado con Backup | X14: 45973
